<mujoco model="onshape">
  <compiler angle="degree" autolimits="true"/>
  <statistic meansize="0.0605485" extent="0.280133" center="-0.0298222 -1.37955e-06 -0.0866556"/>
  <asset>
    <mesh name="left_hip_servomount" file="left_hip_servomount.stl"/>
    <mesh name="electronics_mount002" file="electronics_mount002.stl"/>
    <mesh name="bridge" file="bridge.stl"/>
    <mesh name="right_hip" file="right_hip.stl"/>
    <mesh name="servo" file="servo.stl"/>
    <mesh name="thigh" file="thigh.stl"/>
    <mesh name="right_knee" file="right_knee.stl"/>
    <mesh name="right_foot" file="right_foot.stl"/>
    <mesh name="left_knee_mount" file="left_knee_mount.stl"/>
    <mesh name="left_foot_servomount" file="left_foot_servomount.stl"/>
    <texture builtin="gradient" height="100" rgb1=".4 .5 .6" rgb2="0 0 0" type="skybox" width="100"/>
    <!-- <texture builtin="gradient" height="100" rgb1="1 1 1" rgb2="0 0 0" type="skybox" width="100"/>-->
    <texture builtin="flat" height="1278" mark="cross" markrgb="1 1 1" name="texgeom" random="0.01" rgb1="0.8 0.6 0.4" rgb2="0.8 0.6 0.4" type="cube" width="127"/>
    <texture builtin="checker" height="100" name="texplane" rgb1="0 0 0" rgb2="0.8 0.8 0.8" type="2d" width="100"/>
    <material name="MatPlane" reflectance="0.5" shininess="1" specular="1" texrepeat="60 60" texture="texplane"/>
    <material name="geom" texture="texgeom" texuniform="true"/>
    <hfield name='hf1' nrow='200' ncol='200' size="5 5 .2 .1"/>
  </asset>
  <worldbody>
    <body name="floor" pos="0 0 0">
      <geom name='hfield1' pos='0.0 0 -0.1' hfield='hf1' type='hfield' condim='3' conaffinity='15' friction="1 .1 .1"/> 
    </body>
    <body name="root" pos="0 0 0.4">
      <joint armature="0" damping="0" limited="false" name="root_joint" pos="0 0 0" stiffness="0" type="free"/>
      <geom pos="0.110112 -0.0939423 -0.177698" quat="0.707107 0.707107 0 0" type="mesh" rgba="0.0980392 0.0980392 0.0980392 1" mesh="left_hip_servomount"/>
      <geom pos="0.110112 0.0925647 -0.177698" quat="0.707107 0.707107 0 0" type="mesh" rgba="0.0980392 0.0980392 0.0980392 1" mesh="electronics_mount002"/>
      <geom pos="0.110112 0.0925647 -0.177698" quat="0.707107 0.707107 0 0" type="mesh" rgba="0.0980392 0.0980392 0.0980392 1" mesh="bridge"/>
      <geom pos="0.110112 0.0939387 -0.177698" quat="0.707107 0.707107 0 0" type="mesh" rgba="0.0980392 0.0980392 0.0980392 1" mesh="right_hip"/>
      <geom pos="-0.00505 -0.0405018 -0.069367" quat="0.707107 0 -0.707107 0" type="mesh" rgba="1 1 1 1" mesh="servo"/>
      <geom pos="-0.00505 0.0404981 -0.069267" quat="0 0.707107 0 0.707107" type="mesh" rgba="1 1 1 1" mesh="servo"/>
      <body name="thigh" pos="-0.00505 0.0143981 -0.079347" quat="0.707107 -0.707107 0 0">
        <inertial pos="-0.0160697 0.0191511 -0.002" quat="0.298836 0.640856 -0.298836 0.640856" mass="0.00822824" diaginertia="3.70762e-06 3.29184e-06 4.37721e-07"/>
        <joint name="right_hip_joint" pos="0 0 0" axis="0 0 1" damping="0.1" range="-45 45"/>
        <geom pos="0.0823728 -0.0598292 -0.0839405" type="mesh" rgba="0.0980392 0.0980392 0.0980392 1" mesh="thigh"/>
        <body name="right_knee" pos="-0.0321394 0.0383022 0" quat="0 0.707107 0.707107 0">
          <inertial pos="0.0102946 -0.00114228 -0.0279349" quat="0.633298 -0.273201 -0.26811 0.672616" mass="0.104143" diaginertia="4.04863e-05 2.7562e-05 2.13674e-05"/>
          <joint name="right_knee_joint" pos="0 0 0" axis="0 0 1" damping="0.1" range="-45 45"/>
          <geom pos="0.01008 0 -0.0261" quat="0.707107 0.707107 0 0" type="mesh" rgba="1 1 1 1" mesh="servo"/>
          <geom pos="0.0479115 -0.113862 -0.0795405" quat="0 0.707107 -0.707107 0" type="mesh" rgba="0.0980392 0.0980392 0.0980392 1" mesh="right_knee"/>
          <body name="right_foot" pos="0.05683 0.00065 -0.0591666" quat="0 -0.966391 0.257078 0">
            <inertial pos="0.00688821 0.00770729 -0.0277825" quat="0.542344 0.798817 -0.199621 -0.167051" mass="0.104274" diaginertia="3.48797e-05 2.20392e-05 2.15597e-05"/>
            <joint name="right_foot_joint" pos="0 0 0" axis="0 0 1" damping="0.1" range="-45 45"/>
            <geom pos="0.0261343 -0.0471065 -0.000859459" type="mesh" rgba="0.0980392 0.0980392 0.0980392 1" mesh="right_foot" name="right_foot_servomount"/>
            <geom pos="0.00571293 0.00859505 -0.0289" quat="0.612372 -0.612372 -0.353553 0.353553" type="mesh" rgba="1 1 1 1" mesh="servo"/>
          </body>
        </body>
      </body>
      <body name="thigh_2" pos="-0.00505 -0.0144018 -0.079447" quat="0.707107 0.707107 0 0">
        <inertial pos="-0.0160697 -0.0191511 -0.002" quat="0.640856 0.298836 -0.640856 0.298836" mass="0.00822824" diaginertia="3.70762e-06 3.29184e-06 4.37721e-07"/>
        <joint name="left_hip_joint" pos="0 0 0" axis="0 0 1" damping="0.1" range="-45 45"/>
        <geom pos="0.0823728 0.0598292 0.0799405" quat="0 -1 0 0" type="mesh" rgba="0.0980392 0.0980392 0.0980392 1" mesh="thigh"/>
        <body name="left_knee" pos="-0.0321394 -0.0383022 0" quat="0 0.707107 -0.707107 0">
          <inertial pos="0.0102945 0.00114233 -0.0279349" quat="0.672614 -0.268115 -0.273203 0.633296" mass="0.104143" diaginertia="4.04865e-05 2.75621e-05 2.13676e-05"/>
          <joint name="left_knee_joint" pos="0 0 0" axis="0 0 1" damping="0.1" range="-45 45"/>
          <geom pos="0.01008 0 -0.0261" quat="0.707107 0.707107 0 0" type="mesh" rgba="1 1 1 1" mesh="servo"/>
          <geom pos="-0.00733636 0.100909 -0.0795405" quat="0.422618 0 0 0.906308" type="mesh" rgba="0.0980392 0.0980392 0.0980392 1" mesh="left_knee_mount"/>
          <body name="left_foot" pos="0.05683 -0.000650001 -0.0591666" quat="0 -0.161911 0.986805 0">
            <inertial pos="-0.00541766 0.00871073 -0.0277825" quat="0.543596 0.820645 0.131215 0.117592" mass="0.104274" diaginertia="3.48806e-05 2.2053e-05 2.15468e-05"/>
            <joint name="left_foot_joint" pos="0 0 0" axis="0 0 1" damping="0.1" range="-45 45"/>
            <geom pos="0.180524 0.068949 -0.000859459" quat="0 1 0 0" type="mesh" rgba="0.0980392 0.0980392 0.0980392 1" mesh="left_foot_servomount" name="left_foot_servomount"/>
            <geom pos="-0.0040994 0.00936255 -0.0289" quat="0.40558 -0.40558 -0.579228 0.579228" type="mesh" rgba="1 1 1 1" mesh="servo"/>
          </body>
        </body>
      </body>
    </body>
  </worldbody>
  <actuator>
    <general name="act_left_hip_joint" joint="left_hip_joint" ctrlrange="-1 1" gainprm="1 0 0" ctrllimited="true"/>
    <general name="act_right_hip_joint" joint="right_hip_joint" ctrlrange="-1 1" gainprm="1 0 0" ctrllimited="true"/>
    <general name="act_left_knee_joint" joint="left_knee_joint" ctrlrange="-1 1" gainprm="1 0 0" ctrllimited="true"/>
    <general name="act_right_knee_joint" joint="right_knee_joint" ctrlrange="-1 1" gainprm="1 0 0" ctrllimited="true"/>
    <general name="act_left_foot_joint" joint="left_foot_joint" ctrlrange="-1 1" gainprm="0.5 0 0" ctrllimited="true"/>
    <general name="act_right_foot_joint" joint="right_foot_joint" ctrlrange="-1 1" gainprm="0.5 0 0" ctrllimited="true"/>
  </actuator>
</mujoco>
