<robot name="onshape">
<link name="rigid_body">
<visual>
<origin xyz="0.13638132762946292287 -0.02546605626595017241 -0.0026722904270224008549" rpy="1.5707963267948970021 7.1821472499178763301e-29 -2.4646650490209707448e-30" />
<geometry>
<mesh filename="package:///left_hip_servomount.stl"/>
</geometry>
<material name="left_hip_servomount_material">
<color rgba="0.098039215686274508443 0.098039215686274508443 0.098039215686274508443 1.0"/>
</material>
</visual>
<collision>
<origin xyz="0.13638132762946292287 -0.02546605626595017241 -0.0026722904270224008549" rpy="1.5707963267948970021 7.1821472499178763301e-29 -2.4646650490209707448e-30" />
<geometry>
<mesh filename="package:///left_hip_servomount.stl"/>
</geometry>
</collision>
<visual>
<origin xyz="0.13638132702497735016 0.16104094821055378595 -0.0026722899955154318097" rpy="1.5707963267948970021 -0 0" />
<geometry>
<mesh filename="package:///electronics_mount002.stl"/>
</geometry>
<material name="electronics_mount002_material">
<color rgba="0.098039215686274508443 0.098039215686274508443 0.098039215686274508443 1.0"/>
</material>
</visual>
<collision>
<origin xyz="0.13638132702497735016 0.16104094821055378595 -0.0026722899955154318097" rpy="1.5707963267948970021 -0 0" />
<geometry>
<mesh filename="package:///electronics_mount002.stl"/>
</geometry>
</collision>
<visual>
<origin xyz="0.13638132702497735016 0.16104094751822417564 -0.0026722913949904121556" rpy="1.5707963267948970021 7.1821472499181263218e-29 -2.4646650490209816049e-30" />
<geometry>
<mesh filename="package:///bridge.stl"/>
</geometry>
<material name="bridge_material">
<color rgba="0.098039215686274508443 0.098039215686274508443 0.098039215686274508443 1.0"/>
</material>
</visual>
<collision>
<origin xyz="0.13638132702497735016 0.16104094751822417564 -0.0026722913949904121556" rpy="1.5707963267948970021 7.1821472499181263218e-29 -2.4646650490209816049e-30" />
<geometry>
<mesh filename="package:///bridge.stl"/>
</geometry>
</collision>
<visual>
<origin xyz="0.1363813276835623145 0.16241495188223983859 -0.0026722904243585872408" rpy="1.5707963267948970021 7.1821472499178763301e-29 -2.4646650490209707448e-30" />
<geometry>
<mesh filename="package:///right_hip.stl"/>
</geometry>
<material name="right_hip_material">
<color rgba="0.098039215686274508443 0.098039215686274508443 0.098039215686274508443 1.0"/>
</material>
</visual>
<collision>
<origin xyz="0.1363813276835623145 0.16241495188223983859 -0.0026722904243585872408" rpy="1.5707963267948970021 7.1821472499178763301e-29 -2.4646650490209707448e-30" />
<geometry>
<mesh filename="package:///right_hip.stl"/>
</geometry>
</collision>
<visual>
<origin xyz="0.021219150623029883751 0.027974486336582039814 0.10565916248713735914" rpy="1.1241267899399418227e-29 -1.5707963267948961139 0" />
<geometry>
<mesh filename="package:///servo.stl"/>
</geometry>
<material name="servo_material">
<color rgba="1 1 1 1.0"/>
</material>
</visual>
<collision>
<origin xyz="0.021219150623029883751 0.027974486336582039814 0.10565916248713735914" rpy="1.1241267899399418227e-29 -1.5707963267948961139 0" />
<geometry>
<mesh filename="package:///servo.stl"/>
</geometry>
</collision>
<visual>
<origin xyz="0.021219150685801671519 0.10897440927969853641 0.10575916432720605664" rpy="3.141592653589793116 -1.570796326794896336 0" />
<geometry>
<mesh filename="package:///servo.stl"/>
</geometry>
<material name="servo_material">
<color rgba="1 1 1 1.0"/>
</material>
</visual>
<collision>
<origin xyz="0.021219150685801671519 0.10897440927969853641 0.10575916432720605664" rpy="3.141592653589793116 -1.570796326794896336 0" />
<geometry>
<mesh filename="package:///servo.stl"/>
</geometry>
</collision>
<inertial>
<origin xyz="0.020592930941467520872 0.068474601896326564576 0.11635094569749412918" rpy="0 0 0"/>
<mass value="0.24723777363222709802" />
<inertia ixx="0.00058430773070887540716" ixy="-1.4998808016560108728e-10"  ixz="-8.9177301830160386585e-06" iyy="0.00020786784253187242863" iyz="-3.3070201806919028798e-07" izz="0.00039474331446601721623" />
</inertial>
</link>

<link name="thigh">
<visual>
<origin xyz="0.082372795353104211191 -0.059829232391998374285 -0.083940544128418004277" rpy="-2.8395911100035659387e-30 4.6839174690069999291e-30 1.5034733325320854917e-45" />
<geometry>
<mesh filename="package:///thigh.stl"/>
</geometry>
<material name="thigh_material">
<color rgba="0.098039215686274508443 0.098039215686274508443 0.098039215686274508443 1.0"/>
</material>
</visual>
<collision>
<origin xyz="0.082372795353104211191 -0.059829232391998374285 -0.083940544128418004277" rpy="-2.8395911100035659387e-30 4.6839174690069999291e-30 1.5034733325320854917e-45" />
<geometry>
<mesh filename="package:///thigh.stl"/>
</geometry>
</collision>
<inertial>
<origin xyz="-0.016069690385836943314 0.019151111621288782749 -0.001999999962049747726" rpy="0 0 0"/>
<mass value="0.0082282406087242354609" />
<inertia ixx="2.1125881488524032404e-06" ixy="1.4053802242845183345e-06"  ixz="-2.0391151486593852991e-15" iyy="1.6169756264329329716e-06" iyz="9.3339822441278936158e-16" izz="3.7076218003669738157e-06" />
</inertial>
</link>

<link name="right_knee">
<visual>
<origin xyz="0.010079999999999998683 0 -0.026099999999999998201" rpy="1.570796326794896558 2.0029671422599732111e-32 -1.5034733324267024618e-45" />
<geometry>
<mesh filename="package:///servo.stl"/>
</geometry>
<material name="servo_material">
<color rgba="1 1 1 1.0"/>
</material>
</visual>
<collision>
<origin xyz="0.010079999999999998683 0 -0.026099999999999998201" rpy="1.570796326794896558 2.0029671422599732111e-32 -1.5034733324267024618e-45" />
<geometry>
<mesh filename="package:///servo.stl"/>
</geometry>
</collision>
<visual>
<origin xyz="0.047911454684577844954 -0.11386217671413802199 -0.0795405426025273532" rpy="3.141592653589793116 5.9544925650057125032e-30 -1.570796326794896558" />
<geometry>
<mesh filename="package:///right_knee.stl"/>
</geometry>
<material name="right_knee_material">
<color rgba="0.098039215686274508443 0.098039215686274508443 0.098039215686274508443 1.0"/>
</material>
</visual>
<collision>
<origin xyz="0.047911454684577844954 -0.11386217671413802199 -0.0795405426025273532" rpy="3.141592653589793116 5.9544925650057125032e-30 -1.570796326794896558" />
<geometry>
<mesh filename="package:///right_knee.stl"/>
</geometry>
</collision>
<inertial>
<origin xyz="0.010294556206789250499 -0.0011422773360175205847 -0.027934897340686482697" rpy="0 0 0"/>
<mass value="0.1041428080992812949" />
<inertia ixx="2.4495219172319990621e-05" ixy="-6.9110612264273909614e-07"  ixz="3.1141733274203842427e-06" iyy="4.0444372646747411186e-05" iyz="-2.9632977487709439269e-07" izz="2.4476101629142893651e-05" />
</inertial>
</link>

<link name="right_foot">
<visual>
<origin xyz="0.026134283564461062432 -0.047106454447310611156 -0.00085945868492101618052" rpy="-8.1902170832052477998e-32 -1.328403655348007957e-31 1.3646531962337717647e-17" />
<geometry>
<mesh filename="package:///right_foot.stl"/>
</geometry>
<material name="right_foot_material">
<color rgba="0.098039215686274508443 0.098039215686274508443 0.098039215686274508443 1.0"/>
</material>
</visual>
<collision>
<origin xyz="0.026134283564461062432 -0.047106454447310611156 -0.00085945868492101618052" rpy="-8.1902170832052477998e-32 -1.328403655348007957e-31 1.3646531962337717647e-17" />
<geometry>
<mesh filename="package:///right_foot.stl"/>
</geometry>
</collision>
<visual>
<origin xyz="0.0057129324107874010497 0.0085950524627889796081 -0.028899999761580752455" rpy="-1.57079632679489678 1.7009603572740503363e-16 1.0471975511965978534" />
<geometry>
<mesh filename="package:///servo.stl"/>
</geometry>
<material name="servo_material">
<color rgba="1 1 1 1.0"/>
</material>
</visual>
<collision>
<origin xyz="0.0057129324107874010497 0.0085950524627889796081 -0.028899999761580752455" rpy="-1.57079632679489678 1.7009603572740503363e-16 1.0471975511965978534" />
<geometry>
<mesh filename="package:///servo.stl"/>
</geometry>
</collision>
<inertial>
<origin xyz="0.0068882090809774358664 0.0077072949384917001023 -0.027782483328416054946" rpy="0 0 0"/>
<mass value="0.10427361278879899997" />
<inertia ixx="3.1523431394211588589e-05" ixy="-5.7369582306863344651e-06"  ixz="-6.415042267195733327e-07" iyy="2.4944154283748737571e-05" iyz="1.869099014546125179e-07" izz="2.2011011270975611121e-05" />
</inertial>
</link>

<joint name="right_foot" type="revolute">
<origin xyz="0.056830000134848498994 0.00064999955300205566888 -0.05916663169859820437" rpy="-3.141592653589793116 6.4673233319424062448e-30 -0.51999566909108541068" />
<parent link="right_knee" />
<child link="right_foot" />
<axis xyz="0 0 1"/>
<limit effort="1" velocity="20" />
<joint_properties friction="0.0"/>
</joint>

<joint name="right_knee" type="revolute">
<origin xyz="-0.032139381159561331014 0.038302222075878779306 -4.1633363423443370266e-17" rpy="3.141592653589793116 -6.9333477998915039054e-32 1.570796326794896558" />
<parent link="thigh" />
<child link="right_knee" />
<axis xyz="0 0 1"/>
<limit effort="1" velocity="20" />
<joint_properties friction="0.0"/>
</joint>

<joint name="right_hip" type="revolute">
<origin xyz="0.021219150685801671519 0.082874409279697441866 0.095679164327205606932" rpy="-1.570796326794896336 7.1821472499178763301e-29 -3.451266460341929714e-31" />
<parent link="rigid_body" />
<child link="thigh" />
<axis xyz="0 0 1"/>
<limit effort="1" velocity="20" />
<joint_properties friction="0.0"/>
</joint>

<link name="thigh_2">
<visual>
<origin xyz="0.082372795371358276117 0.059829232407236032643 0.079940544128417945213" rpy="-3.141592653589793116 6.1710949000659996011e-30 0" />
<geometry>
<mesh filename="package:///thigh.stl"/>
</geometry>
<material name="thigh_material">
<color rgba="0.098039215686274508443 0.098039215686274508443 0.098039215686274508443 1.0"/>
</material>
</visual>
<collision>
<origin xyz="0.082372795371358276117 0.059829232407236032643 0.079940544128417945213" rpy="-3.141592653589793116 6.1710949000659996011e-30 0" />
<geometry>
<mesh filename="package:///thigh.stl"/>
</geometry>
</collision>
<inertial>
<origin xyz="-0.016069690367582878388 -0.019151111606051124392 -0.0020000000379503113379" rpy="0 0 0"/>
<mass value="0.0082282406087242354609" />
<inertia ixx="2.1125881488524032404e-06" ixy="-1.4053802242845183345e-06"  ixz="2.0391151486593852991e-15" iyy="1.6169756264329329716e-06" iyz="9.3339822441278936158e-16" izz="3.7076218003669738157e-06" />
</inertial>
</link>

<link name="left_knee">
<visual>
<origin xyz="0.010079999999999991744 0 -0.02610000000000000514" rpy="1.570796326794896558 -0 0" />
<geometry>
<mesh filename="package:///servo.stl"/>
</geometry>
<material name="servo_material">
<color rgba="1 1 1 1.0"/>
</material>
</visual>
<collision>
<origin xyz="0.010079999999999991744 0 -0.02610000000000000514" rpy="1.570796326794896558 -0 0" />
<geometry>
<mesh filename="package:///servo.stl"/>
</geometry>
</collision>
<visual>
<origin xyz="-0.0073363618013047512956 0.1009087116867803946 -0.079540542602539010542" rpy="-4.0915352745497513101e-17 -6.5837917367453452097e-17 2.2689280275926284602" />
<geometry>
<mesh filename="package:///left_knee_mount.stl"/>
</geometry>
<material name="left_knee_mount_material">
<color rgba="0.098039215686274508443 0.098039215686274508443 0.098039215686274508443 1.0"/>
</material>
</visual>
<collision>
<origin xyz="-0.0073363618013047512956 0.1009087116867803946 -0.079540542602539010542" rpy="-4.0915352745497513101e-17 -6.5837917367453452097e-17 2.2689280275926284602" />
<geometry>
<mesh filename="package:///left_knee_mount.stl"/>
</geometry>
</collision>
<inertial>
<origin xyz="0.010294533732697078166 0.001142328551409071578 -0.027934858480738823661" rpy="0 0 0"/>
<mass value="0.10414342813860140435" />
<inertia ixx="2.4495320519744272095e-05" ixy="6.9115145135671883426e-07"  ixz="3.1141290227536674695e-06" iyy="4.0444602743735498334e-05" iyz="2.9628705431686313611e-07" izz="2.447632631552939774e-05" />
</inertial>
</link>

<link name="left_foot">
<visual>
<origin xyz="0.18052418512967013942 0.068948971826897104132 -0.00085945868492100056801" rpy="3.141592653589793116 -1.0758516953671302487e-31 -4.3678779235018684304e-17" />
<geometry>
<mesh filename="package:///left_foot_servomount.stl"/>
</geometry>
<material name="left_foot_servomount_material">
<color rgba="0.098039215686274508443 0.098039215686274508443 0.098039215686274508443 1.0"/>
</material>
</visual>
<collision>
<origin xyz="0.18052418512967013942 0.068948971826897104132 -0.00085945868492100056801" rpy="3.141592653589793116 -1.0758516953671302487e-31 -4.3678779235018684304e-17" />
<geometry>
<mesh filename="package:///left_foot_servomount.stl"/>
</geometry>
</collision>
<visual>
<origin xyz="-0.0040994049283441941212 0.0093625518420303675132 -0.028899999761580998786" rpy="-1.5707963267948958919 4.8666831050848168081e-16 1.9198621771937622871" />
<geometry>
<mesh filename="package:///servo.stl"/>
</geometry>
<material name="servo_material">
<color rgba="1 1 1 1.0"/>
</material>
</visual>
<collision>
<origin xyz="-0.0040994049283441941212 0.0093625518420303675132 -0.028899999761580998786" rpy="-1.5707963267948958919 4.8666831050848168081e-16 1.9198621771937622871" />
<geometry>
<mesh filename="package:///servo.stl"/>
</geometry>
</collision>
<inertial>
<origin xyz="-0.0054176632111181200271 0.0087107282887511489067 -0.02778247672536730134" rpy="0 0 0"/>
<mass value="0.10427362265243660111" />
<inertia ixx="3.3280068212902123501e-05" ixy="4.2755302705480945695e-06"  ixz="6.7051239928648470812e-07" iyy="2.3188402284132182891e-05" iyz="5.5378691432117259288e-08" izz="2.2011864660759350031e-05" />
</inertial>
</link>

<joint name="left_foot" type="revolute">
<origin xyz="0.056830000071431546749 -0.00065000055707029220919 -0.059166631698607578815" rpy="-3.1415926535897926719 1.78374355072504558e-16 -2.8163391732010532031" />
<parent link="left_knee" />
<child link="left_foot" />
<axis xyz="0 0 1"/>
<limit effort="1" velocity="20" />
<joint_properties friction="0.0"/>
</joint>

<joint name="left_knee" type="revolute">
<origin xyz="-0.032139381142254105916 -0.038302222060531534997 -6.2450045135165055399e-17" rpy="3.141592653589793116 -0 -1.570796326794896558" />
<parent link="thigh_2" />
<child link="left_knee" />
<axis xyz="0 0 1"/>
<limit effort="1" velocity="20" />
<joint_properties friction="0.0"/>
</joint>

<joint name="left_hip" type="revolute">
<origin xyz="0.021219150623029883751 0.054074486336582044954 0.095579162487137395154" rpy="1.5707963267948970021 -2.2204460492503130808e-16 1.1241267899399416826e-29" />
<parent link="rigid_body" />
<child link="thigh_2" />
<axis xyz="0 0 1"/>
<limit effort="1" velocity="20" />
<joint_properties friction="0.0"/>
</joint>


</robot>
