<robot name="onshape">
<link name="rigid_body">
<visual>
<origin xyz="0.11011217559218555717 -0.093942327061748071015 -0.17769844818860497382" rpy="1.5707963267948970021 7.1821472499178763301e-29 -2.4646650490209707448e-30" />
<geometry>
<mesh filename="package:///left_hip_servomount.stl"/>
</geometry>
<material name="left_hip_servomount_material">
<color rgba="0.098039215686274508443 0.098039215686274508443 0.098039215686274508443 1.0"/>
</material>
</visual>
<collision>
<origin xyz="0.11011217559218555717 -0.093942327061748071015 -0.17769844818860497382" rpy="1.5707963267948970021 7.1821472499178763301e-29 -2.4646650490209707448e-30" />
<geometry>
<mesh filename="package:///left_hip_servomount.stl"/>
</geometry>
</collision>
<visual>
<origin xyz="0.1101121749877000261 0.092564677414755824891 -0.17769844775709797702" rpy="1.570796326794896558 4.1721355666000002694e-30 4.0711572930420000859e-30" />
<geometry>
<mesh filename="package:///electronics_mount002.stl"/>
</geometry>
<material name="electronics_mount002_material">
<color rgba="0.098039215686274508443 0.098039215686274508443 0.098039215686274508443 1.0"/>
</material>
</visual>
<collision>
<origin xyz="0.1101121749877000261 0.092564677414755824891 -0.17769844775709797702" rpy="1.570796326794896558 4.1721355666000002694e-30 4.0711572930420000859e-30" />
<geometry>
<mesh filename="package:///electronics_mount002.stl"/>
</geometry>
</collision>
<visual>
<origin xyz="0.1101121749877000261 0.092564676722426270095 -0.17769844915657298512" rpy="1.5707963267948970021 7.1821472499181263218e-29 -2.4646650490209816049e-30" />
<geometry>
<mesh filename="package:///bridge.stl"/>
</geometry>
<material name="bridge_material">
<color rgba="0.098039215686274508443 0.098039215686274508443 0.098039215686274508443 1.0"/>
</material>
</visual>
<collision>
<origin xyz="0.1101121749877000261 0.092564676722426270095 -0.17769844915657298512" rpy="1.5707963267948970021 7.1821472499181263218e-29 -2.4646650490209816049e-30" />
<geometry>
<mesh filename="package:///bridge.stl"/>
</geometry>
</collision>
<visual>
<origin xyz="0.11011217564628493493 0.093938681086441933044 -0.1776984481859411602" rpy="1.5707963267948970021 7.1821472499178763301e-29 -2.4646650490209707448e-30" />
<geometry>
<mesh filename="package:///right_hip.stl"/>
</geometry>
<material name="right_hip_material">
<color rgba="0.098039215686274508443 0.098039215686274508443 0.098039215686274508443 1.0"/>
</material>
</visual>
<collision>
<origin xyz="0.11011217564628493493 0.093938681086441933044 -0.1776984481859411602" rpy="1.5707963267948970021 7.1821472499178763301e-29 -2.4646650490209707448e-30" />
<geometry>
<mesh filename="package:///right_hip.stl"/>
</geometry>
</collision>
<visual>
<origin xyz="-0.0050500014142475097012 -0.040501784459215442458 -0.069366995274444190334" rpy="1.1241267899399418227e-29 -1.5707963267948961139 0" />
<geometry>
<mesh filename="package:///servo.stl"/>
</geometry>
<material name="servo_material">
<color rgba="1 1 1 1.0"/>
</material>
</visual>
<collision>
<origin xyz="-0.0050500014142475097012 -0.040501784459215442458 -0.069366995274444190334" rpy="1.1241267899399418227e-29 -1.5707963267948961139 0" />
<geometry>
<mesh filename="package:///servo.stl"/>
</geometry>
</collision>
<visual>
<origin xyz="-0.0050500013514757392807 0.040498138483900644746 -0.069266993434376533667" rpy="3.141592653589793116 -1.570796326794896336 0" />
<geometry>
<mesh filename="package:///servo.stl"/>
</geometry>
<material name="servo_material">
<color rgba="1 1 1 1.0"/>
</material>
</visual>
<collision>
<origin xyz="-0.0050500013514757392807 0.040498138483900644746 -0.069266993434376533667" rpy="3.141592653589793116 -1.570796326794896336 0" />
<geometry>
<mesh filename="package:///servo.stl"/>
</geometry>
</collision>
<inertial>
<origin xyz="-0.0056762210958098621716 -1.6688994712087581607e-06 -0.058675212064088086428" rpy="0 0 0"/>
<mass value="0.24723777363222709802" />
<inertia ixx="0.00058430773070887128719" ixy="-1.4998808009741493503e-10"  ixz="-8.9177301830162792159e-06" iyy="0.00020786784253187112759" iyz="-3.3070201806530071268e-07" izz="0.00039474331446601445151" />
</inertial>
</link>

<link name="thigh">
<visual>
<origin xyz="0.082372795353104211191 -0.059829232391998388163 -0.083940544128418018155" rpy="-2.8395911100035659387e-30 4.6839174690069999291e-30 1.5034733325320854917e-45" />
<geometry>
<mesh filename="package:///thigh.stl"/>
</geometry>
<material name="thigh_material">
<color rgba="0.098039215686274508443 0.098039215686274508443 0.098039215686274508443 1.0"/>
</material>
</visual>
<collision>
<origin xyz="0.082372795353104211191 -0.059829232391998388163 -0.083940544128418018155" rpy="-2.8395911100035659387e-30 4.6839174690069999291e-30 1.5034733325320854917e-45" />
<geometry>
<mesh filename="package:///thigh.stl"/>
</geometry>
</collision>
<inertial>
<origin xyz="-0.016069690385836943314 0.019151111621288768871 -0.0019999999620497754815" rpy="0 0 0"/>
<mass value="0.0082282406087242389303" />
<inertia ixx="2.1125881488524032404e-06" ixy="1.4053802242845183345e-06"  ixz="-2.0391151486593872713e-15" iyy="1.6169756264329331833e-06" iyz="9.3339822441294871149e-16" izz="3.7076218003669742392e-06" />
</inertial>
</link>

<link name="right_knee">
<visual>
<origin xyz="0.010080000000000005622 0 -0.026100000000000001671" rpy="1.570796326794896558 2.0029671422599732111e-32 -1.5034733324267024618e-45" />
<geometry>
<mesh filename="package:///servo.stl"/>
</geometry>
<material name="servo_material">
<color rgba="1 1 1 1.0"/>
</material>
</visual>
<collision>
<origin xyz="0.010080000000000005622 0 -0.026100000000000001671" rpy="1.570796326794896558 2.0029671422599732111e-32 -1.5034733324267024618e-45" />
<geometry>
<mesh filename="package:///servo.stl"/>
</geometry>
</collision>
<visual>
<origin xyz="0.047911454684577831076 -0.11386217671413800812 -0.079540542602527339322" rpy="3.141592653589793116 5.9544925650057125032e-30 -1.570796326794896558" />
<geometry>
<mesh filename="package:///right_knee.stl"/>
</geometry>
<material name="right_knee_material">
<color rgba="0.098039215686274508443 0.098039215686274508443 0.098039215686274508443 1.0"/>
</material>
</visual>
<collision>
<origin xyz="0.047911454684577831076 -0.11386217671413800812 -0.079540542602527339322" rpy="3.141592653589793116 5.9544925650057125032e-30 -1.570796326794896558" />
<geometry>
<mesh filename="package:///right_knee.stl"/>
</geometry>
</collision>
<inertial>
<origin xyz="0.010294556206789248765 -0.0011422773360175195005 -0.027934897340686482697" rpy="0 0 0"/>
<mass value="0.10414280809928128102" />
<inertia ixx="2.4495219172319977069e-05" ixy="-6.9110612264273581389e-07"  ixz="3.114173327420379584e-06" iyy="4.0444372646747384081e-05" iyz="-2.9632977487709063398e-07" izz="2.4476101629142869935e-05" />
</inertial>
</link>

<link name="right_foot">
<visual>
<origin xyz="0.026134283564461041616 -0.047106454447310604217 -0.00085945868492100230274" rpy="-8.1902170832052477998e-32 -1.328403655348007957e-31 1.3646531962337717647e-17" />
<geometry>
<mesh filename="package:///right_foot.stl"/>
</geometry>
<material name="right_foot_material">
<color rgba="0.098039215686274508443 0.098039215686274508443 0.098039215686274508443 1.0"/>
</material>
</visual>
<collision>
<origin xyz="0.026134283564461041616 -0.047106454447310604217 -0.00085945868492100230274" rpy="-8.1902170832052477998e-32 -1.328403655348007957e-31 1.3646531962337717647e-17" />
<geometry>
<mesh filename="package:///right_foot.stl"/>
</geometry>
</collision>
<visual>
<origin xyz="0.005712932410787380233 0.0085950524627889310358 -0.028899999761581016133" rpy="-1.57079632679489678 1.7009603572740503363e-16 1.0471975511965978534" />
<geometry>
<mesh filename="package:///servo.stl"/>
</geometry>
<material name="servo_material">
<color rgba="1 1 1 1.0"/>
</material>
</visual>
<collision>
<origin xyz="0.005712932410787380233 0.0085950524627889310358 -0.028899999761581016133" rpy="-1.57079632679489678 1.7009603572740503363e-16 1.0471975511965978534" />
<geometry>
<mesh filename="package:///servo.stl"/>
</geometry>
</collision>
<inertial>
<origin xyz="0.0068882090809774150497 0.0077072949384916636731 -0.027782483328416263113" rpy="0 0 0"/>
<mass value="0.10427361278879899997" />
<inertia ixx="3.1523431394211683457e-05" ixy="-5.7369582306863378532e-06"  ixz="-6.4150422671960393176e-07" iyy="2.4944154283748839215e-05" iyz="1.8690990145461760009e-07" izz="2.2011011270975600957e-05" />
</inertial>
</link>

<joint name="right_foot" type="revolute">
<origin xyz="0.056830000134848485116 0.00064999955300212852727 -0.059166631698598218247" rpy="-3.141592653589793116 6.4673233319424062448e-30 -0.51999566909108541068" />
<parent link="right_knee" />
<child link="right_foot" />
<axis xyz="0 0 1"/>
<limit effort="1" velocity="20" />
<joint_properties friction="0.0"/>
</joint>

<joint name="right_knee" type="revolute">
<origin xyz="-0.032139381159561331014 0.038302222075878786245 -4.6837533851373791549e-17" rpy="3.141592653589793116 -6.9333477998915039054e-32 1.570796326794896558" />
<parent link="thigh" />
<child link="right_knee" />
<axis xyz="0 0 1"/>
<limit effort="1" velocity="20" />
<joint_properties friction="0.0"/>
</joint>

<joint name="right_hip" type="revolute">
<origin xyz="-0.0050500013514757358113 0.0143981384838995502 -0.079346993434376983378" rpy="-1.570796326794896336 7.1821472499178763301e-29 -3.451266460341929714e-31" />
<parent link="rigid_body" />
<child link="thigh" />
<axis xyz="0 0 1"/>
<limit effort="1" velocity="20" />
<joint_properties friction="0.0"/>
</joint>

<link name="thigh_2">
<visual>
<origin xyz="0.082372795371358289995 0.059829232407236060398 0.079940544128417945213" rpy="-3.141592653589793116 6.1710949000659996011e-30 0" />
<geometry>
<mesh filename="package:///thigh.stl"/>
</geometry>
<material name="thigh_material">
<color rgba="0.098039215686274508443 0.098039215686274508443 0.098039215686274508443 1.0"/>
</material>
</visual>
<collision>
<origin xyz="0.082372795371358289995 0.059829232407236060398 0.079940544128417945213" rpy="-3.141592653589793116 6.1710949000659996011e-30 0" />
<geometry>
<mesh filename="package:///thigh.stl"/>
</geometry>
</collision>
<inertial>
<origin xyz="-0.01606969036758286451 -0.019151111606051096636 -0.0020000000379502974601" rpy="0 0 0"/>
<mass value="0.0082282406087242389303" />
<inertia ixx="2.1125881488524032404e-06" ixy="-1.4053802242845183345e-06"  ixz="2.0391151486593872713e-15" iyy="1.6169756264329331833e-06" iyz="9.3339822441294871149e-16" izz="3.7076218003669742392e-06" />
</inertial>
</link>

<link name="left_knee">
<visual>
<origin xyz="0.010079999999999991744 0 -0.026100000000000001671" rpy="1.570796326794896558 -0 0" />
<geometry>
<mesh filename="package:///servo.stl"/>
</geometry>
<material name="servo_material">
<color rgba="1 1 1 1.0"/>
</material>
</visual>
<collision>
<origin xyz="0.010079999999999991744 0 -0.026100000000000001671" rpy="1.570796326794896558 -0 0" />
<geometry>
<mesh filename="package:///servo.stl"/>
</geometry>
</collision>
<visual>
<origin xyz="-0.0073363618013047443567 0.1009087116867803946 -0.079540542602538982786" rpy="-4.0915352745497513101e-17 -6.5837917367453452097e-17 2.2689280275926284602" />
<geometry>
<mesh filename="package:///left_knee_mount.stl"/>
</geometry>
<material name="left_knee_mount_material">
<color rgba="0.098039215686274508443 0.098039215686274508443 0.098039215686274508443 1.0"/>
</material>
</visual>
<collision>
<origin xyz="-0.0073363618013047443567 0.1009087116867803946 -0.079540542602538982786" rpy="-4.0915352745497513101e-17 -6.5837917367453452097e-17 2.2689280275926284602" />
<geometry>
<mesh filename="package:///left_knee_mount.stl"/>
</geometry>
</collision>
<inertial>
<origin xyz="0.010294533732697078166 0.0011423285514090713612 -0.027934858480738813252" rpy="0 0 0"/>
<mass value="0.10414342813860140435" />
<inertia ixx="2.4495320519744258542e-05" ixy="6.911514513567180931e-07"  ixz="3.114129022753667893e-06" iyy="4.0444602743735478005e-05" iyz="2.9628705431686207732e-07" izz="2.4476326315529401128e-05" />
</inertial>
</link>

<link name="left_foot">
<visual>
<origin xyz="0.18052418512967013942 0.068948971826897104132 -0.00085945868492100230274" rpy="3.141592653589793116 -1.0758516953671302487e-31 -4.3678779235018684304e-17" />
<geometry>
<mesh filename="package:///left_foot_servomount.stl"/>
</geometry>
<material name="left_foot_servomount_material">
<color rgba="0.098039215686274508443 0.098039215686274508443 0.098039215686274508443 1.0"/>
</material>
</visual>
<collision>
<origin xyz="0.18052418512967013942 0.068948971826897104132 -0.00085945868492100230274" rpy="3.141592653589793116 -1.0758516953671302487e-31 -4.3678779235018684304e-17" />
<geometry>
<mesh filename="package:///left_foot_servomount.stl"/>
</geometry>
</collision>
<visual>
<origin xyz="-0.0040994049283441524878 0.0093625518420303779216 -0.028899999761581023072" rpy="-1.5707963267948958919 4.8666831050848168081e-16 1.9198621771937622871" />
<geometry>
<mesh filename="package:///servo.stl"/>
</geometry>
<material name="servo_material">
<color rgba="1 1 1 1.0"/>
</material>
</visual>
<collision>
<origin xyz="-0.0040994049283441524878 0.0093625518420303779216 -0.028899999761581023072" rpy="-1.5707963267948958919 4.8666831050848168081e-16 1.9198621771937622871" />
<geometry>
<mesh filename="package:///servo.stl"/>
</geometry>
</collision>
<inertial>
<origin xyz="-0.0054176632111180905368 0.0087107282887511541108 -0.027782476725367325626" rpy="0 0 0"/>
<mass value="0.10427362265243658723" />
<inertia ixx="3.3280068212902123501e-05" ixy="4.2755302705480869463e-06"  ixz="6.7051239928649931944e-07" iyy="2.3188402284132199831e-05" iyz="5.5378691432122315016e-08" izz="2.2011864660759363583e-05" />
</inertial>
</link>

<joint name="left_foot" type="revolute">
<origin xyz="0.056830000071432587583 -0.00065000055707035292452 -0.05916663169860798821" rpy="-3.1415926535897926719 1.78374355072504558e-16 -2.8163391732010532031" />
<parent link="left_knee" />
<child link="left_foot" />
<axis xyz="0 0 1"/>
<limit effort="1" velocity="20" />
<joint_properties friction="0.0"/>
</joint>

<joint name="left_knee" type="revolute">
<origin xyz="-0.032139381142254119794 -0.038302222060531507242 -5.7245874707234634116e-17" rpy="3.141592653589793116 -0 -1.570796326794896558" />
<parent link="thigh_2" />
<child link="left_knee" />
<axis xyz="0 0 1"/>
<limit effort="1" velocity="20" />
<joint_properties friction="0.0"/>
</joint>

<joint name="left_hip" type="revolute">
<origin xyz="-0.0050500014142475097012 -0.014401784459215430378 -0.079446995274444182078" rpy="1.5707963267948970021 -2.2204460492503130808e-16 1.1241267899399416826e-29" />
<parent link="rigid_body" />
<child link="thigh_2" />
<axis xyz="0 0 1"/>
<limit effort="1" velocity="20" />
<joint_properties friction="0.0"/>
</joint>


</robot>
